<mujoco>
  <option timestep="0.0005" integrator="implicitfast" cone="elliptic"/>

  <extension>
    <plugin plugin="mujoco.ros2">
      <instance name="micras">
        <config key="ros_namespace" value="micras/"/>
        <config key="topic_queue_size" value="1"/>
      </instance>
    </plugin>
  </extension>

  <asset>
    <texture name="grid" type="2d" builtin="checker" width="512" height="512" rgb1=".1 .1 .1" rgb2=".2 .2 .2"/>
    <material name="grid" texture="grid" texrepeat="5.5555555555 5.5555555555" texuniform="true" reflectance=".2"/>

    <model name="maze" file="maze.xml"/>

    <mesh name="base" scale="0.001 0.001 0.001"
        vertex=" 31.0 -33.0 -0.5
                 33.0  41.0 -0.5
                 15.5  66.0 -0.5

                -31.0 -33.0 -0.5
                -33.0  41.0 -0.5
                -15.5  66.0 -0.5

                 31.0 -33.0  0.5
                 33.0  41.0  0.5
                 15.5  66.0  0.5

                -31.0 -33.0  0.5
                -33.0  41.0  0.5
                -15.5  66.0  0.5
    "/>
  </asset>

  <default>
    <default class="wheel">
      <joint type="hinge" frictionloss="0.000645"/>
      <geom type="cylinder" size=".011 .004" rgba=".5 .5 1 1" condim="6" friction="0.95 0.004 0.001" priority="1"/>
      <site type="box" rgba=".5 1 .5 1" size="0.01 0.001 0.0041"/>
    </default>
    <default class="dc_motor">
        <general biastype="affine" gainprm="0.000106 0 0" biasprm="0 0 -0.0000115" gear="10"/>
    </default>
  </default>

  <worldbody>
    <attach model="maze" prefix="maze_"/>

    <geom name="floor" type="plane" size="0 0 .01" pos="0 0 0" material="grid"/>
    <light name="ambient_light" pos="0 0 3" dir="0 0 -1" directional="true" castshadow="false"/>

    <body name="micras" pos="0.09 0.05 .03">
      <freejoint/>

      <camera name="overhead"      mode="track" pos=" 0.000  0.000 0.500" euler=" 0 0 0"  fovy="60"/>
      <camera name="side tracking" mode="track" pos="-0.469 -0.469 0.663" xyaxes="0.707 -0.707 0.000 0.500 0.500 0.707"/>
      <camera name="robot pov"     mode="fixed" pos=" 0.000  0.040 0.030" euler="90 0 0"  fovy="80"/>

      <site name="imu"/>
      <site name="lidar_0" pos="-0.026 0.041 0.02" zaxis=" 0 1 0"/>
      <site name="lidar_1" pos="-0.01  0.061 0.02" zaxis="-1 1 0"/>
      <site name="lidar_2" pos=" 0.01  0.061 0.02" zaxis=" 1 1 0"/>
      <site name="lidar_3" pos=" 0.026 0.041 0.02" zaxis=" 0 1 0"/>

      <geom name="base" type="mesh" mesh="base" mass="0.08" rgba="0.0 0.4 0.2 1" contype="1" conaffinity="1"/>
      <geom name="front wheel" pos="0.0 0.06 -0.0003" type="sphere" size=".001" friction="0.05" priority="1"/>

      <body name="left_wheel" pos="-0.031 0.0 0.01" zaxis="-1 0 0">
        <joint name="left_wheel" class="wheel"/>
        <geom name="left_wheel" class="wheel"/>
        <site class="wheel"/>
      </body>
      <body name="right_wheel" pos="0.031 0.0 0.01" zaxis="-1 0 0">
        <joint name="right_wheel" class="wheel"/>
        <geom name="right_wheel" class="wheel"/>
        <site class="wheel"/>
      </body>
    </body>
  </worldbody>

  <actuator>
    <general name="motor_left" class="dc_motor" joint="left_wheel"/>
    <general name="motor_right" class="dc_motor" joint="right_wheel"/>
  </actuator>

  <sensor>
    <jointactuatorfrc name="torque_left"  joint="left_wheel"/>
    <jointactuatorfrc name="torque_right" joint="right_wheel"/>

    <gyro name="gyro" site="imu"/>
    <accelerometer name="accelerometer" site="imu"/>

    <jointpos name="encoder_left" joint="left_wheel"/>
    <jointpos name="encoder_right" joint="right_wheel"/>

    <rangefinder name="lidar_0" site="lidar_0"/>
    <rangefinder name="lidar_1" site="lidar_1"/>
    <rangefinder name="lidar_2" site="lidar_2"/>
    <rangefinder name="lidar_3" site="lidar_3"/>
  </sensor>
</mujoco>
