<?xml version="1.0" ?>
<sdf version="1.8">
  <model name="robot" canonical_link="base_link">
    <link name="base_link">
      <inertial>
        <mass>0.0206254177502013</mass>
        <inertia>
          <ixx>1.78587720432087E-05</ixx>
          <ixy>0</ixy>
          <ixz>0</ixz>
          <iyy>5.6820499519587E-06</iyy>
          <iyz>0</iyz>
          <izz>2.35320218169273E-05</izz>
        </inertia>
      </inertial>
      <visual name="base_vis">
        <pose relative_to="base_link">0 0.07 0.017 0 0 0</pose>
        <geometry>
          <mesh>
            <uri>file://gazebo/meshes/base_link.stl</uri>
          </mesh> 
        </geometry>
        <material>
          <ambient>0.0 0.5 0.0 1</ambient>
          <diffuse>0.0 0.5 0.0 1</diffuse>
          <specular>0.0 0.5 0.0 1</specular>
        </material>
      </visual>
      <collision name="base_coll">
        <pose relative_to="base_link">0 0.07 0.017 0 0 0</pose>
        <geometry>
          <mesh>
            <uri>file://gazebo/meshes/base_link.stl</uri>
          </mesh> 
        </geometry>
      </collision>
    </link>
    <link name="FLW_link">
      <pose relative_to="base_link">-0.0275 -0.002 0.008 0 0 3.14159265359</pose>
      <inertial>
        <mass>0.00135156970824209</mass>
        <inertia>
          <ixx>8.00075362261772E-08</ixx>
          <ixy>0</ixy>
          <ixz>0</ixz>
          <iyy>4.82352157196683E-08</iyy>
          <iyz>0</iyz>
          <izz>4.82352157196683E-08</izz>
        </inertia>
      </inertial>
      <visual name="FLW_vis">
        <pose relative_to="FLW_link">-0.00425 0 0 0 0 3.14159265359</pose>
        <geometry>
          <mesh>
            <uri>file://gazebo/meshes/wheel.stl</uri>
          </mesh>
        </geometry>
        <material>
          <ambient>1.0 0.7 0 1</ambient>
          <diffuse>1.0 0.7 0 1</diffuse>
          <specular>1.0 0.7 0 1</specular>
        </material>
      </visual>
      <collision name="FLW_coll">
        <pose relative_to="FLW_link">-0.00425 0 0 0 0 3.14159265359</pose>
        <geometry>
          <mesh>
            <uri>file://gazebo/meshes/wheel.stl</uri>
          </mesh>
        </geometry>
        <surface>
          <friction>
            <ode>
              <mu>1.0</mu>
              <mu2>0.0</mu2>
              <fdir1 gz:expressed_in="base_link">1 -1 0</fdir1>
            </ode>
            <bullet>
              <friction>1</friction>
              <friction2>1</friction2>
              <rolling_friction>0.1</rolling_friction>
            </bullet>
          </friction>
        </surface>
      </collision>
    </link>
    <joint name="FLW_joint" type="revolute">
      <pose relative_to='FLW_link'/>
      <parent>base_link</parent>
      <child>FLW_link</child>
      <axis>
        <xyz>1 0 0</xyz>
        <limit>
          <lower>-1.79769e+308</lower>
          <upper>1.79769e+308</upper>
        </limit>
      </axis>
    </joint>
    <link name="RLW_link">
      <pose relative_to="base_link">-0.0275 -0.025 0.008 0 0 3.14159265359</pose>
      <inertial>
        <mass>0.00135156970824209</mass>
        <inertia>
          <ixx>8.00075362261772E-08</ixx>
          <ixy>0</ixy>
          <ixz>0</ixz>
          <iyy>4.82352157196683E-08</iyy>
          <iyz>0</iyz>
          <izz>4.82352157196683E-08</izz>
        </inertia>
      </inertial>
      <visual name="RLW_vis">
        <pose relative_to="RLW_link">-0.00425 0 0 0 0 3.14159265359</pose>
        <geometry>
          <mesh>
            <uri>file://gazebo/meshes/wheel.stl</uri>
          </mesh>
        </geometry>
        <material>
          <ambient>1.0 0.7 0 1</ambient>
          <diffuse>1.0 0.7 0 1</diffuse>
          <specular>1.0 0.7 0 1</specular>
        </material>
      </visual>
      <collision name="RLW_coll">
        <pose relative_to="RLW_link">-0.00425 0 0 0 0 3.14159265359</pose>
        <geometry>
          <mesh>
            <uri>file://gazebo/meshes/wheel.stl</uri>
          </mesh>
        </geometry>
        <surface>
          <friction>
            <ode>
              <mu>1.0</mu>
              <mu2>0.0</mu2>
              <fdir1 gz:expressed_in="base_link">1 -1 0</fdir1>
            </ode>
            <bullet>
              <friction>1</friction>
              <friction2>1</friction2>
              <rolling_friction>0.1</rolling_friction>
            </bullet>
          </friction>
        </surface>
      </collision>
    </link>
    <joint name="RLW_joint" type="revolute">
      <pose relative_to='RLW_link'/>
      <parent>base_link</parent>
      <child>RLW_link</child>
      <axis>
        <xyz>1 0 0</xyz>
        <limit>
          <lower>-1.79769e+308</lower>
          <upper>1.79769e+308</upper>
        </limit>
      </axis>
    </joint>
    <link name="FRW_link">
      <pose relative_to="base_link">0.0285 -0.002 0.008 0 0 3.14159265359</pose>
      <inertial>
        <mass>0.00135156970824209</mass>
        <inertia>
          <ixx>8.00075362261772E-08</ixx>
          <ixy>0</ixy>
          <ixz>0</ixz>
          <iyy>4.82352157196683E-08</iyy>
          <iyz>0</iyz>
          <izz>4.82352157196683E-08</izz>
        </inertia>
      </inertial>
      <visual name="FRW_vis">
        <pose relative_to="FRW_link">0.00425 0 0 0 0 0</pose>
        <geometry>
          <mesh>
            <uri>file://gazebo/meshes/wheel.stl</uri>
          </mesh>
        </geometry>
        <material>
          <ambient>1.0 0.7 0 1</ambient>
          <diffuse>1.0 0.7 0 1</diffuse>
          <specular>1.0 0.7 0 1</specular>
        </material>
      </visual>
      <collision name="FRW_coll">
        <pose relative_to="FRW_link">0.00425 0 0 0 0 0</pose>
        <geometry>
          <mesh>
            <uri>file://gazebo/meshes/wheel.stl</uri>
          </mesh>
        </geometry>
        <surface>
          <friction>
            <ode>
              <mu>1.0</mu>
              <mu2>0.0</mu2>
              <fdir1 gz:expressed_in="base_link">1 -1 0</fdir1>
            </ode>
            <bullet>
              <friction>1</friction>
              <friction2>1</friction2>
              <rolling_friction>0.1</rolling_friction>
            </bullet>
          </friction>
        </surface>
      </collision>
    </link>
    <joint name="FRW_joint" type="revolute">
      <pose relative_to='FRW_link'/>
      <parent>base_link</parent>
      <child>FRW_link</child>
      <axis>
        <xyz>1 0 0</xyz>
        <limit>
          <lower>-1.79769e+308</lower>
          <upper>1.79769e+308</upper>
        </limit>
      </axis>
    </joint>
    <link name="RRW_link">
      <pose relative_to="base_link">0.0285 -0.025 0.008 0 0 3.14159265359</pose>
      <inertial>
        <mass>0.00135156970824209</mass>
        <inertia>
          <ixx>8.00075362261772E-08</ixx>
          <ixy>0</ixy>
          <ixz>0</ixz>
          <iyy>4.82352157196683E-08</iyy>
          <iyz>0</iyz>
          <izz>4.82352157196683E-08</izz>
        </inertia>
      </inertial>
      <visual name="RRW_vis">
        <pose relative_to="RRW_link">0.00425 0 0 0 0 0</pose>
        <geometry>
          <mesh>
            <uri>file://gazebo/meshes/wheel.stl</uri>
          </mesh>
        </geometry>
        <material>
          <ambient>1.0 0.7 0 1</ambient>
          <diffuse>1.0 0.7 0 1</diffuse>
          <specular>1.0 0.7 0 1</specular>
        </material>
      </visual>
      <collision name="RRW_coll">
        <pose relative_to="RRW_link">0.00425 0 0 0 0 0</pose>
        <geometry>
          <mesh>
            <uri>file://gazebo/meshes/wheel.stl</uri>
          </mesh>
        </geometry>
        <surface>
          <friction>
            <ode>
              <mu>1.0</mu>
              <mu2>0.0</mu2>
              <fdir1 gz:expressed_in="base_link">1 -1 0</fdir1>
            </ode>
            <bullet>
              <friction>1</friction>
              <friction2>1</friction2>
              <rolling_friction>0.1</rolling_friction>
            </bullet>
          </friction>
        </surface>
      </collision>
    </link>
    <joint name="RRW_joint" type="revolute">
      <pose relative_to='RRW_link'/>
      <parent>base_link</parent>
      <child>RRW_link</child>
      <axis>
        <xyz>1 0 0</xyz>
        <limit>
          <lower>-1.79769e+308</lower>
          <upper>1.79769e+308</upper>
        </limit>
      </axis>
    </joint>
  </model>
</sdf>
